<?xml version="1.0" ?>
<!-- =================================================================================== -->
<!-- |    This document was autogenerated by xacro from src/clumsybot_description/urdf/clumsybot.urdf.xacro | -->
<!-- |    EDITING THIS FILE BY HAND IS NOT RECOMMENDED                                 | -->
<!-- =================================================================================== -->
<robot name="clumsybot" xmlns:xacro="http://www.ros.org/wiki/xacro">
  <material name="black">
    <color rgba="0.0 0.0 0.0 1.0"/>
  </material>
  <material name="blue">
    <color rgba="0.0 0.0 0.8 1.0"/>
  </material>
  <material name="green">
    <color rgba="0.0 0.8 0.0 1.0"/>
  </material>
  <material name="grey">
    <color rgba="0.2 0.2 0.2 1.0"/>
  </material>
  <material name="orange">
    <color rgba="1.0 0.4235294117647059 0.0392156862745098 1.0"/>
  </material>
  <material name="brown">
    <color rgba="0.8705882352941177 0.8117647058823529 0.7647058823529411 1.0"/>
  </material>
  <material name="red">
    <color rgba="0.8 0.0 0.0 1.0"/>
  </material>
  <material name="white">
    <color rgba="1.0 1.0 1.0 1.0"/>
  </material>
  <material name="metalic">
    <color rgba="0.8 0.8 0.9 1"/>
  </material>
  <material name="wheel_color">
    <color rgba="0.1 0.1 0.1 1"/>
  </material>
  <!-- ros_control plugin -->
  <!-- <gazebo>
    <plugin name="gazebo_ros_control" filename="libgazebo_ros_control.so">
      <robotNamespace>/</robotNamespace>
      <robotSimType>gazebo_ros_control/DefaultRobotHWSim</robotSimType>
    </plugin>
  </gazebo> -->
  <gazebo reference="base_link">
    <material>Gazebo/Gray</material>
  </gazebo>
  <gazebo reference="hat_link">
    <material>Gazebo/Blue</material>
  </gazebo>
  <gazebo>
    <plugin filename="libgazebo_ros_diff_drive.so" name="differential_drive_controller">
      <update_rate>20</update_rate>
      <num_wheel_pairs>2</num_wheel_pairs>
      <left_joint>left_front_wheel_joint</left_joint>
      <left_joint>left_back_wheel_joint</left_joint>
      <right_joint>right_front_wheel_joint</right_joint>
      <right_joint>right_back_wheel_joint</right_joint>
      <wheel_separation>0.197</wheel_separation>
      <wheel_separation>0.197</wheel_separation>
      <wheel_diameter>0.042</wheel_diameter>
      <wheel_diameter>0.042</wheel_diameter>
      <wheel_acceleration>0.5</wheel_acceleration>
      <torque>1</torque>
      <publish_odom>true</publish_odom>
      <publish_wheel_tf>true</publish_wheel_tf>
      <publish_odom_tf>true</publish_odom_tf>
      <odometry_frame>odom</odometry_frame>
      <robot_base_frame>base_footprint</robot_base_frame>
    </plugin>
  </gazebo>
  <link name="base_link">
    <visual>
      <geometry>
        <box size="0.145 0.19 0.23"/>
      </geometry>
      <origin rpy="0 0 0" xyz="0 0 0.115"/>
      <material name="metalic"/>
    </visual>
    <collision>
      <origin rpy="0 0 0" xyz="0 0 0.13"/>
      <geometry>
        <box size="0.145 0.21 0.26"/>
      </geometry>
    </collision>
    <inertial>
      <origin xyz="0 0 0.115"/>
      <mass value="2"/>
      <inertia ixx="1.0e-3" ixy="0.0" ixz="0.0" iyy="1.0e-3" iyz="0.0" izz="1.0e-3"/>
    </inertial>
  </link>
  <link name="base_footprint"/>
  <joint name="base_joint" type="fixed">
    <parent link="base_footprint"/>
    <child link="base_link"/>
    <origin rpy="0 0 0" xyz="0.0 0.0 0.005"/>
  </joint>
  <link name="hat_link">
    <visual>
      <geometry>
        <box size="0.155 0.2 0.03"/>
      </geometry>
      <material name="blue"/>
    </visual>
    <inertial>
      <mass value="0.5"/>
      <inertia ixx="0" ixy="0.0" ixz="0.0" iyy="0" iyz="0.0" izz="0"/>
    </inertial>
  </link>
  <joint name="base_to_hat" type="fixed">
    <parent link="base_link"/>
    <child link="hat_link"/>
    <origin xyz="0 0 0.23"/>
  </joint>
  <link name="left_front_wheel">
    <visual>
      <geometry>
        <cylinder length="0.007" radius="0.021"/>
      </geometry>
      <material name="wheel_color"/>
      <origin rpy="1.570795 0 0"/>
    </visual>
    <collision>
      <geometry>
        <cylinder length="0.007" radius="0.021"/>
      </geometry>
      <origin rpy="1.570795 0 0"/>
    </collision>
    <inertial>
      <mass value="0.01"/>
      <inertia ixx="1.0e-5" ixy="0.0" ixz="0.0" iyy="1.0e-5" iyz="0.0" izz="1.0e-5"/>
    </inertial>
  </link>
  <joint name="left_front_wheel_joint" type="continuous">
    <axis xyz="0 1 0"/>
    <parent link="base_link"/>
    <child link="left_front_wheel"/>
    <origin xyz="-0.05149999999999999 0.095 0.016"/>
  </joint>
  <link name="left_back_wheel">
    <visual>
      <geometry>
        <cylinder length="0.007" radius="0.021"/>
      </geometry>
      <material name="wheel_color"/>
      <origin rpy="1.570795 0 0"/>
    </visual>
    <collision>
      <geometry>
        <cylinder length="0.007" radius="0.021"/>
      </geometry>
      <origin rpy="1.570795 0 0"/>
    </collision>
    <inertial>
      <mass value="0.01"/>
      <inertia ixx="1.0e-5" ixy="0.0" ixz="0.0" iyy="1.0e-5" iyz="0.0" izz="1.0e-5"/>
    </inertial>
  </link>
  <joint name="left_back_wheel_joint" type="continuous">
    <mimic joint="left_front_wheel_joint" multiplier="1" offset="0"/>
    <axis xyz="0 1 0"/>
    <parent link="base_link"/>
    <child link="left_back_wheel"/>
    <origin xyz="0.05149999999999999 0.095 0.016"/>
  </joint>
  <link name="right_front_wheel">
    <visual>
      <geometry>
        <cylinder length="0.007" radius="0.021"/>
      </geometry>
      <material name="wheel_color"/>
      <origin rpy="1.570795 0 0"/>
    </visual>
    <collision>
      <geometry>
        <cylinder length="0.007" radius="0.021"/>
      </geometry>
      <origin rpy="1.570795 0 0"/>
    </collision>
    <inertial>
      <mass value="0.01"/>
      <inertia ixx="1.0e-5" ixy="0.0" ixz="0.0" iyy="1.0e-5" iyz="0.0" izz="1.0e-5"/>
    </inertial>
  </link>
  <joint name="right_front_wheel_joint" type="continuous">
    <axis xyz="0 1 0"/>
    <parent link="base_link"/>
    <child link="right_front_wheel"/>
    <origin xyz="-0.05149999999999999 -0.095 0.016"/>
  </joint>
  <link name="right_back_wheel">
    <visual>
      <geometry>
        <cylinder length="0.007" radius="0.021"/>
      </geometry>
      <origin rpy="1.570795 0 0"/>
      <material name="wheel_color"/>
    </visual>
    <collision>
      <geometry>
        <cylinder length="0.007" radius="0.021"/>
      </geometry>
      <origin rpy="1.570795 0 0"/>
    </collision>
    <inertial>
      <mass value="0.01"/>
      <inertia ixx="1.0e-5" ixy="0.0" ixz="0.0" iyy="1.0e-5" iyz="0.0" izz="1.0e-5"/>
    </inertial>
  </link>
  <joint name="right_back_wheel_joint" type="continuous">
    <mimic joint="right_front_wheel_joint" multiplier="1" offset="0"/>
    <axis xyz="0 1 0"/>
    <parent link="base_link"/>
    <child link="right_back_wheel"/>
    <origin xyz="0.05149999999999999 -0.095 0.016"/>
  </joint>
  <link name="camera_link">
    <visual>
      <material name="black"/>
      <geometry>
        <box size="0.02 0.18 0.02"/>
      </geometry>
    </visual>
    <collision>
      <origin xyz="0 0 0.041"/>
      <geometry>
        <box size="0.065 0.25 0.082"/>
      </geometry>
    </collision>
    <inertial>
      <mass value="0.935"/>
      <inertia ixx="0.0053937" ixy="0" ixz="0" iyy="0.00085311" iyz="0" izz="0.00519899"/>
    </inertial>
    <mu1>0.2</mu1>
    <mu2>0.2</mu2>
    <material>Gazebo/Black</material>
    <sensor name="openni_depth_camera" type="depth">
      <always_on>1</always_on>
      <visualize>true</visualize>
      <camera>
        <horizontal_fov>1.047</horizontal_fov>
        <image>
          <width>640</width>
          <height>480</height>
          <format>R8G8B8</format>
        </image>
        <depth_camera>

            </depth_camera>
        <clip>
          <near>0.1</near>
          <far>100</far>
        </clip>
      </camera>
      <plugin filename="libgazebo_ros_openni_kinect.so" name="camera_controller">
        <alwaysOn>true</alwaysOn>
        <updateRate>10.0</updateRate>
        <cameraName>camera</cameraName>
        <frameName>kinect_rgb_optical_frame</frameName>
        <imageTopicName>/image_raw</imageTopicName>
        <depthImageTopicName>depth/image_raw</depthImageTopicName>
        <pointCloudTopicName>depth/points</pointCloudTopicName>
        <cameraInfoTopicName>/camera_info</cameraInfoTopicName>
        <depthImageCameraInfoTopicName>depth/camera_info</depthImageCameraInfoTopicName>
        <pointCloudCutoff>0.4</pointCloudCutoff>
        <hackBaseline>0.07</hackBaseline>
        <distortionK1>0.0</distortionK1>
        <distortionK2>0.0</distortionK2>
        <distortionK3>0.0</distortionK3>
        <distortionT1>0.0</distortionT1>
        <distortionT2>0.0</distortionT2>
        <CxPrime>0.0</CxPrime>
        <Cx>0.0</Cx>
        <Cy>0.0</Cy>
        <focalLength>0.0</focalLength>
      </plugin>
    </sensor>
  </link>
  <joint name="kinect_to_hat_joint" type="fixed">
    <parent link="hat_link"/>
    <child link="camera_link"/>
    <origin xyz="0 0 0.06"/>
  </joint>
  <link name="kinect_rgb_optical_frame"/>
  <joint name="rgb_kinect_joint" type="fixed">
    <origin rpy="1.570795 3.14159 1.570795"/>
    <parent link="camera_link"/>
    <child link="kinect_rgb_optical_frame"/>
  </joint>
  <link name="proximity_sensor_link">
    <collision>
      <geometry>
        <box size="0.01 0.01 0.01"/>
      </geometry>
      <origin xyz="-0.01 0 0"/>
    </collision>
    <visual>
      <geometry>
        <box size="0.01 0.01 0.01"/>
      </geometry>
    </visual>
    <inertial>
      <mass value="0.114"/>
      <origin xyz="0 0 0"/>
      <inertia ixx="0.001" ixy="0.0" ixz="0.0" iyy="0.001" iyz="0.0" izz="0.001"/>
    </inertial>
  </link>
  <joint name="proximity_sensor_joint" type="fixed">
    <origin rpy="0 0 0" xyz="0.08 0 0"/>
    <parent link="hat_link"/>
    <child link="proximity_sensor_link"/>
  </joint>
  <gazebo reference="proximity_sensor_link">
    <sensor name="proximity_sensor" type="ray">
      <frame name="proximity_sensor_link"/>
      <visualize>true</visualize>
      <update_rate>10</update_rate>
      <always_on>true</always_on>
      <ray>
        <scan>
          <horizontal>
            <samples>1</samples>
            <resolution>1</resolution>
            <min_angle>-0.5005</min_angle>
            <max_angle>0.5005</max_angle>
          </horizontal>
          <vertical>
            <samples>1</samples>
            <resolution>1</resolution>
            <min_angle>-0.5005</min_angle>
            <max_angle>0.5005</max_angle>
          </vertical>
        </scan>
        <range>
          <min>0.0</min>
          <max>2.5</max>
          <resolution>0.005</resolution>
        </range>
        <noise>
          <type>gaussian</type>
          <mean>0.0</mean>
          <stddev>0.0025</stddev>
        </noise>
      </ray>
      <plugin filename="libgazebo_ros_ray_sensor.so" name="proximity_sensor_controller">
        <radiation_type>infrared</radiation_type>
        <ros>
          <argument>~/out:=scan</argument>
        </ros>
        <!-- <output_type>sensor_msgs/Range</output_type> -->
        <output_type>sensor_msgs/LaserScan</output_type>
      </plugin>
      <plugin filename="libgazebo_ros_ray_sensor.so" name="proximity_sensor_controller_pc2">
        <ros>
          <remapping>~/out:=pointcloud2</remapping>
        </ros>
        <output_type>sensor_msgs/PointCloud2</output_type>
      </plugin>
      <plugin filename="libgazebo_ros_ray_sensor.so" name="proximity_sensor_controller_range">
        <ros>
          <remapping>~/out:=range</remapping>
        </ros>
      </plugin>
    </sensor>
    <material>Gazebo/DarkGrey</material>
  </gazebo>
  <!-- <transmission name="left_wheel_transmission">
    <type>transmission_interface/SimpleTransmission</type>
    <joint name="left_front_wheel_joint">
      <hardwareInterface>hardware_interface/VelocityJointInterface</hardwareInterface>
    </joint>
    <actuator name="left_wheel_actuator">
      <mechanicalReduction>7</mechanicalReduction>
      <hardwareInterface>VelocityJointInterface</hardwareInterface>
    </actuator>
  </transmission>

  <transmission name="right_wheel_transmission">
    <type>transmission_interface/SimpleTransmission</type>
    <joint name="right_front_wheel_joint">
      <hardwareInterface>hardware_interface/VelocityJointInterface</hardwareInterface>
    </joint>
    <actuator name="right_wheel_actuator">
      <mechanicalReduction>7</mechanicalReduction>
      <hardwareInterface>VelocityJointInterface</hardwareInterface>
    </actuator>
  </transmission> -->
</robot>
